Workbook

Sheet Worcestershire 2025 Raw Data
A1: collision_index | B1: collision_year | C1: collision_ref_no | D1: location_easting_osgr | E1: location_northing_osgr | F1: longitude | G1: latitude | H1: police_force | I1: collision_severity | J1: collision_severity_text | K1: number_of_vehicles | L1: number_of_casualties | M1: date | N1: day_of_week | O1: day_of_week | P1: time | Q1: local_authority_district | R1: local_authority_ons_district | S1: local_authority_highway | T1: local_authority_highway_current | U1: first_road_class | V1: first_road_class_text | W1: first_road_number | X1: Road Number Final | Y1: road_type | Z1: road_type_text | AA1: speed_limit | AB1: junction_detail_historic | AC1: junction_detail | AD1: junction_control | AE1: second_road_class | AF1: second_road_number | AG1: pedestrian_crossing_human_control_historic | AH1: pedestrian_crossing_physical_facilities_historic | AI1: pedestrian_crossing | AJ1: light_conditions | AK1: light_conditions_text | AL1: weather_conditions | AM1: weather_conditions_text | AN1: road_surface_conditions | AO1: road_surface_conditions_text | AP1: special_conditions_at_site | AQ1: carriageway_hazards_historic | AR1: carriageway_hazards | AS1: urban_or_rural_area | AT1: did_police_officer_attend_scene_of_accident | AU1: trunk_road_flag | AV1: lsoa_of_accident_location | AW1: enhanced_severity_collision | AX1: collision_injury_based | AY1: collision_adjusted_severity_serious | AZ1: collision_adjusted_severity_slight
A2: 2025221567733 | B2: 2025 | C2: 221567733 | D2: 384636 | E2: 279562 | F2: -2.22731 | G2: 52.41384 | H2: 22 | I2: 3 | J2: =VLOOKUP(I2, Lookups!$B$1:$C$4, 2, FALSE) -> Slight | K2: 2 | L2: 1 | M2: 45737 | N2: 6 | O2: =VLOOKUP(N2, Lookups!$B$6:$C$12, 2, FALSE) -> Friday | P2: 0.55694444 | Q2: -1 | R2: E07000239 | S2: E10000034 | T2: E10000034 | U2: 3 | V2: =VLOOKUP(U2, Lookups!$B$51:$C$57, 2, FALSE) -> A | W2: 449 | X2: =V2&W2 -> A449 | Y2: 6 | Z2: =VLOOKUP(Y2, Lookups!$B$14:$C$21, 2, FALSE) -> Single carriageway | AA2: 60 | AB2: -1 | AC2: 13 | AD2: 4 | AE2: 6 | AF2: 0 | AG2: -1 | AH2: -1 | AI2: 0 | AJ2: 1 | AK2: =VLOOKUP(AJ2, Lookups!$B$23:$C$28, 2, FALSE) -> Daylight | AL2: 1 | AM2: =VLOOKUP(AL2, Lookups!$B$30:$C$39, 2, FALSE) -> Fine / Clear | AN2: 1 | AO2: =VLOOKUP(AN2, Lookups!$B$41:$C$49, 2, FALSE) -> Dry | AP2: -1 | AQ2: -1 | AR2: 0 | AS2: 2 | AT2: 1 | AU2: 2 | AV2: E01032440 | AW2: 3 | AX2: 1 | AY2: 0 | AZ2: 1
A3: 2025221588675 | B3: 2025 | C3: 221588675 | D3: 395304 | E3: 269898 | F3: -2.07033 | G3: 52.32715 | H3: 22 | I3: 3 | J3: =VLOOKUP(I3, Lookups!$B$1:$C$4, 2, FALSE) -> Slight | K3: 2 | L3: 1 | M3: 45787 | N3: 7 | O3: =VLOOKUP(N3, Lookups!$B$6:$C$12, 2, FALSE) -> Saturday | P3: 0.73958333 | Q3: -1 | R3: E07000234 | S3: E10000034 | T3: E10000034 | U3: 4 | V3: =VLOOKUP(U3, Lookups!$B$51:$C$57, 2, FALSE) -> B | W3: 4091 | X3: =V3&W3 -> B4091 | Y3: 1 | Z3: =VLOOKUP(Y3, Lookups!$B$14:$C$21, 2, FALSE) -> Roundabout | AA3: 30 | AB3: -1 | AC3: -1 | AD3: 4 | AE3: 6 | AF3: 0 | AG3: -1 | AH3: -1 | AI3: 0 | AJ3: 1 | AK3: =VLOOKUP(AJ3, Lookups!$B$23:$C$28, 2, FALSE) -> Daylight | AL3: 1 | AM3: =VLOOKUP(AL3, Lookups!$B$30:$C$39, 2, FALSE) -> Fine / Clear | AN3: 1 | AO3: =VLOOKUP(AN3, Lookups!$B$41:$C$49, 2, FALSE) -> Dry | AP3: -1 | AQ3: -1 | AR3: 0 | AS3: 1 | AT3: 1 | AU3: 2 | AV3: E01032131 | AW3: 3 | AX3: 1 | AY3: 0 | AZ3: 1
A4: 2025221635237 | B4: 2025 | C4: 221635237 | D4: 386597 | E4: 246424 | F4: -2.19715 | G4: 52.11597 | H4: 22 | I4: 3 | J4: =VLOOKUP(I4, Lookups!$B$1:$C$4, 2, FALSE) -> Slight | K4: 2 | L4: 1 | M4: 45898 | N4: 6 | O4: =VLOOKUP(N4, Lookups!$B$6:$C$12, 2, FALSE) -> Friday | P4: 0.47916667 | Q4: -1 | R4: E07000235 | S4: E10000034 | T4: E10000034 | U4: 1 | V4: =VLOOKUP(U4, Lookups!$B$51:$C$57, 2, FALSE) -> M | W4: 5 | X4: =V4&W4 -> M5 | Y4: 3 | Z4: =VLOOKUP(Y4, Lookups!$B$14:$C$21, 2, FALSE) -> Dual carriageway | AA4: 70 | AB4: -1 | AC4: 0 | AD4: -1 | AE4: 0 | AF4: -1 | AG4: -1 | AH4: -1 | AI4: 0 | AJ4: 1 | AK4: =VLOOKUP(AJ4, Lookups!$B$23:$C$28, 2, FALSE) -> Daylight | AL4: 1 | AM4: =VLOOKUP(AL4, Lookups!$B$30:$C$39, 2, FALSE) -> Fine / Clear | AN4: 1 | AO4: =VLOOKUP(AN4, Lookups!$B$41:$C$49, 2, FALSE) -> Dry | AP4: -1 | AQ4: -1 | AR4: 0 | AS4: 2 | AT4: 1 | AU4: 1 | AV4: E01032191 | AW4: 3 | AX4: 1 | AY4: 0 | AZ4: 1
A5: 2025221665326 | B5: 2025 | C5: 221665326 | D5: 396313 | E5: 271019 | F5: -2.05554 | G5: 52.33724 | H5: 22 | I5: 3 | J5: =VLOOKUP(I5, Lookups!$B$1:$C$4, 2, FALSE) -> Slight | K5: 1 | L5: 1 | M5: 45968 | N5: 6 | O5: =VLOOKUP(N5, Lookups!$B$6:$C$12, 2, FALSE) -> Friday | P5: 0.35763889 | Q5: -1 | R5: E07000234 | S5: E10000034 | T5: E10000034 | U5: 6 | V5: =VLOOKUP(U5, Lookups!$B$51:$C$57, 2, FALSE) -> Unclassified | W5: 0 | X5: Unclassified | Y5: 6 | Z5: =VLOOKUP(Y5, Lookups!$B$14:$C$21, 2, FALSE) -> Single carriageway | AA5: 20 | AB5: -1 | AC5: 0 | AD5: -1 | AE5: 6 | AF5: 0 | AG5: -1 | AH5: -1 | AI5: 0 | AJ5: 1 | AK5: =VLOOKUP(AJ5, Lookups!$B$23:$C$28, 2, FALSE) -> Daylight | AL5: 1 | AM5: =VLOOKUP(AL5, Lookups!$B$30:$C$39, 2, FALSE) -> Fine / Clear | AN5: 1 | AO5: =VLOOKUP(AN5, Lookups!$B$41:$C$49, 2, FALSE) -> Dry | AP5: -1 | AQ5: -1 | AR5: 0 | AS5: 1 | AT5: 2 | AU5: 2 | AV5: E01032157 | AW5: 3 | AX5: 1 | AY5: 0 | AZ5: 1
A6: 2025221547052 | B6: 2025 | C6: 221547052 | D6: 379093 | E6: 245777 | F6: -2.3067 | G6: 52.10992 | H6: 22 | I6: 3 | J6: =VLOOKUP(I6, Lookups!$B$1:$C$4, 2, FALSE) -> Slight | K6: 1 | L6: 1 | M6: 45683 | N6: 1 | O6: =VLOOKUP(N6, Lookups!$B$6:$C$12, 2, FALSE) -> Sunday | P6: 0.30902778 | Q6: -1 | R6: E07000235 | S6: E10000034 | T6: E10000034 | U6: 6 | V6: =VLOOKUP(U6, Lookups!$B$51:$C$57, 2, FALSE) -> Unclassified | W6: 0 | X6: Unclassified | Y6: 6 | Z6: =VLOOKUP(Y6, Lookups!$B$14:$C$21, 2, FALSE) -> Single carriageway | AA6: 30 | AB6: -1 | AC6: 0 | AD6: -1 | AE6: 6 | AF6: 0 | AG6: -1 | AH6: -1 | AI6: 0 | AJ6: 1 | AK6: =VLOOKUP(AJ6, Lookups!$B$23:$C$28, 2, FALSE) -> Daylight | AL6: 1 | AM6: =VLOOKUP(AL6, Lookups!$B$30:$C$39, 2, FALSE) -> Fine / Clear | AN6: 4 | AO6: =VLOOKUP(AN6, Lookups!$B$41:$C$49, 2, FALSE) -> Frost or ice | AP6: -1 | AQ6: -1 | AR6: 21 | AS6: 1 | AT6: 1 | AU6: 2 | AV6: E01032187 | AW6: 3 | AX6: 1 | AY6: 0 | AZ6: 1
A7: 2025221580738 | B7: 2025 | C7: 221580738 | D7: 391101 | E7: 276898 | F7: -2.13219 | G7: 52.39003 | H7: 22 | I7: 3 | J7: =VLOOKUP(I7, Lookups!$B$1:$C$4, 2, FALSE) -> Slight | K7: 1 | L7: 4 | M7: 45768 | N7: 2 | O7: =VLOOKUP(N7, Lookups!$B$6:$C$12, 2, FALSE) -> Monday | P7: 0.80555556 | Q7: -1 | R7: E07000234 | S7: E10000034 | T7: E10000034 | U7: 6 | V7: =VLOOKUP(U7, Lookups!$B$51:$C$57, 2, FALSE) -> Unclassified | W7: 0 | X7: Unclassified | Y7: 6 | Z7: =VLOOKUP(Y7, Lookups!$B$14:$C$21, 2, FALSE) -> Single carriageway | AA7: 60 | AB7: -1 | AC7: 0 | AD7: -1 | AE7: 0 | AF7: -1 | AG7: -1 | AH7: -1 | AI7: 0 | AJ7: 1 | AK7: =VLOOKUP(AJ7, Lookups!$B$23:$C$28, 2, FALSE) -> Daylight | AL7: 1 | AM7: =VLOOKUP(AL7, Lookups!$B$30:$C$39, 2, FALSE) -> Fine / Clear | AN7: 2 | AO7: =VLOOKUP(AN7, Lookups!$B$41:$C$49, 2, FALSE) -> Wet / damp | AP7: -1 | AQ7: -1 | AR7: 0 | AS7: 2 | AT7: 1 | AU7: 2 | AV7: E01032137 | AW7: 3 | AX7: 1 | AY7: 0 | AZ7: 1
A8: 2025221628403 | B8: 2025 | C8: 221628403 | D8: 388372 | E8: 253896 | F8: -2.17149 | G8: 52.18319 | H8: 22 | I8: 3 | J8: =VLOOKUP(I8, Lookups!$B$1:$C$4, 2, FALSE) -> Slight | K8: 2 | L8: 1 | M8: 45879 | N8: 1 | O8: =VLOOKUP(N8, Lookups!$B$6:$C$12, 2, FALSE) -> Sunday | P8: 0.51736111 | Q8: -1 | R8: E07000238 | S8: E10000034 | T8: E10000034 | U8: 1 | V8: =VLOOKUP(U8, Lookups!$B$51:$C$57, 2, FALSE) -> M | W8: 5 | X8: =V8&W8 -> M5 | Y8: 3 | Z8: =VLOOKUP(Y8, Lookups!$B$14:$C$21, 2, FALSE) -> Dual carriageway | AA8: 70 | AB8: -1 | AC8: 0 | AD8: -1 | AE8: 0 | AF8: -1 | AG8: -1 | AH8: -1 | AI8: 0 | AJ8: 1 | AK8: =VLOOKUP(AJ8, Lookups!$B$23:$C$28, 2, FALSE) -> Daylight | AL8: 1 | AM8: =VLOOKUP(AL8, Lookups!$B$30:$C$39, 2, FALSE) -> Fine / Clear | AN8: 1 | AO8: =VLOOKUP(AN8, Lookups!$B$41:$C$49, 2, FALSE) -> Dry | AP8: -1 | AQ8: -1 | AR8: 0 | AS8: 2 | AT8: 1 | AU8: 1 | AV8: E01032417 | AW8: 3 | AX8: 1 | AY8: 0 | AZ8: 1
A9: 2025221543697 | B9: 2025 | C9: 221543697 | D9: 399672 | E9: 269444 | F9: -2.00623 | G9: 52.32309 | H9: 22 | I9: 3 | J9: =VLOOKUP(I9, Lookups!$B$1:$C$4, 2, FALSE) -> Slight | K9: 1 | L9: 1 | M9: 45676 | N9: 1 | O9: =VLOOKUP(N9, Lookups!$B$6:$C$12, 2, FALSE) -> Sunday | P9: 0.55486111 | Q9: -1 | R9: E07000234 | S9: E10000034 | T9: E10000034 | U9: 3 | V9: =VLOOKUP(U9, Lookups!$B$51:$C$57, 2, FALSE) -> A | W9: 448 | X9: =V9&W9 -> A448 | Y9: 3 | Z9: =VLOOKUP(Y9, Lookups!$B$14:$C$21, 2, FALSE) -> Dual carriageway | AA9: 70 | AB9: -1 | AC9: 0 | AD9: -1 | AE9: 0 | AF9: -1 | AG9: -1 | AH9: -1 | AI9: 0 | AJ9: 1 | AK9: =VLOOKUP(AJ9, Lookups!$B$23:$C$28, 2, FALSE) -> Daylight | AL9: 1 | AM9: =VLOOKUP(AL9, Lookups!$B$30:$C$39, 2, FALSE) -> Fine / Clear | AN9: 1 | AO9: =VLOOKUP(AN9, Lookups!$B$41:$C$49, 2, FALSE) -> Dry | AP9: -1 | AQ9: -1 | AR9: 20 | AS9: 2 | AT9: 1 | AU9: 2 | AV9: E01033060 | AW9: 3 | AX9: 1 | AY9: 0 | AZ9: 1
A10: 2025221572374 | B10: 2025 | C10: 221572374 | D10: 381653 | E10: 270783 | F10: -2.27068 | G10: 52.33482 | H10: 22 | I10: 3 | J10: =VLOOKUP(I10, Lookups!$B$1:$C$4, 2, FALSE) -> Slight | K10: 2 | L10: 1 | M10: 45747 | N10: 2 | O10: =VLOOKUP(N10, Lookups!$B$6:$C$12, 2, FALSE) -> Monday | P10: 0.57986111 | Q10: -1 | R10: E07000239 | S10: E10000034 | T10: E10000034 | U10: 6 | V10: =VLOOKUP(U10, Lookups!$B$51:$C$57, 2, FALSE) -> Unclassified | W10: 0 | X10: Unclassified | Y10: 6 | Z10: =VLOOKUP(Y10, Lookups!$B$14:$C$21, 2, FALSE) -> Single carriageway | AA10: 30 | AB10: -1 | AC10: 19 | AD10: 4 | AE10: 6 | AF10: 0 | AG10: -1 | AH10: -1 | AI10: 0 | AJ10: 1 | AK10: =VLOOKUP(AJ10, Lookups!$B$23:$C$28, 2, FALSE) -> Daylight | AL10: 1 | AM10: =VLOOKUP(AL10, Lookups!$B$30:$C$39, 2, FALSE) -> Fine / Clear | AN10: 1 | AO10: =VLOOKUP(AN10, Lookups!$B$41:$C$49, 2, FALSE) -> Dry | AP10: -1 | AQ10: -1 | AR10: 0 | AS10: 1 | AT10: 1 | AU10: 2 | AV10: E01032461 | AW10: 3 | AX10: 1 | AY10: 0 | AZ10: 1
A11: 2025221594672 | B11: 2025 | C11: 221594672 | D11: 404041 | E11: 247311 | F11: -1.94239 | G11: 52.1241 | H11: 22 | I11: 1 | J11: =VLOOKUP(I11, Lookups!$B$1:$C$4, 2, FALSE) -> Fatal | K11: 4 | L11: 3 | M11: 45802 | N11: 1 | O11: =VLOOKUP(N11, Lookups!$B$6:$C$12, 2, FALSE) -> Sunday | P11: 0.70208333 | Q11: -1 | R11: E07000238 | S11: E10000034 | T11: E10000034 | U11: 4 | V11: =VLOOKUP(U11, Lookups!$B$51:$C$57, 2, FALSE) -> B | W11: 4088 | X11: =V11&W11 -> B4088 | Y11: 6 | Z11: =VLOOKUP(Y11, Lookups!$B$14:$C$21, 2, FALSE) -> Single carriageway | AA11: 50 | AB11: -1 | AC11: 13 | AD11: 4 | AE11: 6 | AF11: 0 | AG11: -1 | AH11: -1 | AI11: 0 | AJ11: 1 | AK11: =VLOOKUP(AJ11, Lookups!$B$23:$C$28, 2, FALSE) -> Daylight | AL11: 1 | AM11: =VLOOKUP(AL11, Lookups!$B$30:$C$39, 2, FALSE) -> Fine / Clear | AN11: 1 | AO11: =VLOOKUP(AN11, Lookups!$B$41:$C$49, 2, FALSE) -> Dry | AP11: -1 | AQ11: -1 | AR11: 0 | AS11: 2 | AT11: 1 | AU11: 2 | AV11: E01032389 | AW11: 1 | AX11: 1 | AY11: 0 | AZ11: 0
A12: 2025221615699 | B12: 2025 | C12: 221615699 | D12: 382081 | E12: 275053 | F12: -2.26463 | G12: 52.37322 | H12: 22 | I12: 3 | J12: =VLOOKUP(I12, Lookups!$B$1:$C$4, 2, FALSE) -> Slight | K12: 1 | L12: 1 | M12: 45838 | N12: 2 | O12: =VLOOKUP(N12, Lookups!$B$6:$C$12, 2, FALSE) -> Monday | P12: 0.47916667 | Q12: -1 | R12: E07000239 | S12: E10000034 | T12: E10000034 | U12: 6 | V12: =VLOOKUP(U12, Lookups!$B$51:$C$57, 2, FALSE) -> Unclassified | W12: 0 | X12: Unclassified | Y12: 6 | Z12: =VLOOKUP(Y12, Lookups!$B$14:$C$21, 2, FALSE) -> Single carriageway | AA12: 30 | AB12: -1 | AC12: 0 | AD12: -1 | AE12: 0 | AF12: -1 | AG12: -1 | AH12: -1 | AI12: 0 | AJ12: 1 | AK12: =VLOOKUP(AJ12, Lookups!$B$23:$C$28, 2, FALSE) -> Daylight | AL12: 1 | AM12: =VLOOKUP(AL12, Lookups!$B$30:$C$39, 2, FALSE) -> Fine / Clear | AN12: 1 | AO12: =VLOOKUP(AN12, Lookups!$B$41:$C$49, 2, FALSE) -> Dry | AP12: -1 | AQ12: -1 | AR12: 0 | AS12: 1 | AT12: 2 | AU12: 2 | AV12: E01034334 | AW12: 3 | AX12: 1 | AY12: 0 | AZ12: 1
A13: 2025221615363 | B13: 2025 | C13: 221615363 | D13: 384918 | E13: 255263 | F13: -2.22207 | G13: 52.19539 | H13: 22 | I13: 3 | J13: =VLOOKUP(I13, Lookups!$B$1:$C$4, 2, FALSE) -> Slight | K13: 2 | L13: 1 | M13: 45851 | N13: 1 | O13: =VLOOKUP(N13, Lookups!$B$6:$C$12, 2, FALSE) -> Sunday | P13: 0.36805556 | Q13: -1 | R13: E07000237 | S13: E10000034 | T13: E10000034 | U13: 3 | V13: =VLOOKUP(U13, Lookups!$B$51:$C$57, 2, FALSE) -> A | W13: 38 | X13: =V13&W13 -> A38 | Y13: 6 | Z13: =VLOOKUP(Y13, Lookups!$B$14:$C$21, 2, FALSE) -> Single carriageway | AA13: 30 | AB13: -1 | AC13: 13 | AD13: 4 | AE13: 6 | AF13: 0 | AG13: -1 | AH13: -1 | AI13: 14 | AJ13: 1 | AK13: =VLOOKUP(AJ13, Lookups!$B$23:$C$28, 2, FALSE) -> Daylight | AL13: 1 | AM13: =VLOOKUP(AL13, Lookups!$B$30:$C$39, 2, FALSE) -> Fine / Clear | AN13: 1 | AO13: =VLOOKUP(AN13, Lookups!$B$41:$C$49, 2, FALSE) -> Dry | AP13: -1 | AQ13: -1 | AR13: 0 | AS13: 1 | AT13: 3 | AU13: 2 | AV13: E01032282 | AW13: 3 | AX13: 1 | AY13: 0 | AZ13: 1
A14: 2025221640829 | B14: 2025 | C14: 221640829 | D14: 381348 | E14: 256866 | F14: -2.27438 | G14: 52.2097 | H14: 22 | I14: 3 | J14: =VLOOKUP(I14, Lookups!$B$1:$C$4, 2, FALSE) -> Slight | K14: 4 | L14: 4 | M14: 45912 | N14: 6 | O14: =VLOOKUP(N14, Lookups!$B$6:$C$12, 2, FALSE) -> Friday | P14: 0.61319444 | Q14: -1 | R14: E07000235 | S14: E10000034 | T14: E10000034 | U14: 4 | V14: =VLOOKUP(U14, Lookups!$B$51:$C$57, 2, FALSE) -> B | W14: 4204 | X14: =V14&W14 -> B4204 | Y14: 6 | Z14: =VLOOKUP(Y14, Lookups!$B$14:$C$21, 2, FALSE) -> Single carriageway | AA14: 30 | AB14: -1 | AC14: 13 | AD14: 4 | AE14: 6 | AF14: 0 | AG14: -1 | AH14: -1 | AI14: 0 | AJ14: 1 | AK14: =VLOOKUP(AJ14, Lookups!$B$23:$C$28, 2, FALSE) -> Daylight | AL14: 2 | AM14: =VLOOKUP(AL14, Lookups!$B$30:$C$39, 2, FALSE) -> Rain | AN14: 2 | AO14: =VLOOKUP(AN14, Lookups!$B$41:$C$49, 2, FALSE) -> Wet / damp | AP14: -1 | AQ14: -1 | AR14: 0 | AS14: 2 | AT14: 1 | AU14: 2 | AV14: E01032183 | AW14: 3 | AX14: 1 | AY14: 0 | AZ14: 1
A15: 2025221648659 | B15: 2025 | C15: 221648659 | D15: 381950 | E15: 273954 | F15: -2.26649 | G15: 52.36334 | H15: 22 | I15: 3 | J15: =VLOOKUP(I15, Lookups!$B$1:$C$4, 2, FALSE) -> Slight | K15: 2 | L15: 2 | M15: 45930 | N15: 3 | O15: =VLOOKUP(N15, Lookups!$B$6:$C$12, 2, FALSE) -> Tuesday | P15: 0.45833333 | Q15: -1 | R15: E07000239 | S15: E10000034 | T15: E10000034 | U15: 3 | V15: =VLOOKUP(U15, Lookups!$B$51:$C$57, 2, FALSE) -> A | W15: 451 | X15: =V15&W15 -> A451 | Y15: 6 | Z15: =VLOOKUP(Y15, Lookups!$B$14:$C$21, 2, FALSE) -> Single carriageway | AA15: 30 | AB15: -1 | AC15: 13 | AD15: 2 | AE15: 6 | AF15: 0 | AG15: -1 | AH15: -1 | AI15: 15 | AJ15: 1 | AK15: =VLOOKUP(AJ15, Lookups!$B$23:$C$28, 2, FALSE) -> Daylight | AL15: 1 | AM15: =VLOOKUP(AL15, Lookups!$B$30:$C$39, 2, FALSE) -> Fine / Clear | AN15: 1 | AO15: =VLOOKUP(AN15, Lookups!$B$41:$C$49, 2, FALSE) -> Dry | AP15: -1 | AQ15: -1 | AR15: 0 | AS15: 1 | AT15: 1 | AU15: 2 | AV15: E01032469 | AW15: 3 | AX15: 1 | AY15: 0 | AZ15: 1
A16: 2025221663636 | B16: 2025 | C16: 221663636 | D16: 382509 | E16: 258941 | F16: -2.2575 | G16: 52.22839 | H16: 22 | I16: 3 | J16: =VLOOKUP(I16, Lookups!$B$1:$C$4, 2, FALSE) -> Slight | K16: 3 | L16: 1 | M16: 45965 | N16: 3 | O16: =VLOOKUP(N16, Lookups!$B$6:$C$12, 2, FALSE) -> Tuesday | P16: 0.64375 | Q16: -1 | R16: E07000235 | S16: E10000034 | T16: E10000034 | U16: 6 | V16: =VLOOKUP(U16, Lookups!$B$51:$C$57, 2, FALSE) -> Unclassified | W16: 0 | X16: Unclassified | Y16: 6 | Z16: =VLOOKUP(Y16, Lookups!$B$14:$C$21, 2, FALSE) -> Single carriageway | AA16: 30 | AB16: -1 | AC16: 18 | AD16: 4 | AE16: 6 | AF16: 0 | AG16: -1 | AH16: -1 | AI16: 0 | AJ16: 1 | AK16: =VLOOKUP(AJ16, Lookups!$B$23:$C$28, 2, FALSE) -> Daylight | AL16: 2 | AM16: =VLOOKUP(AL16, Lookups!$B$30:$C$39, 2, FALSE) -> Rain | AN16: 2 | AO16: =VLOOKUP(AN16, Lookups!$B$41:$C$49, 2, FALSE) -> Wet / damp | AP16: -1 | AQ16: -1 | AR16: 0 | AS16: 2 | AT16: 1 | AU16: 2 | AV16: E01032190 | AW16: 3 | AX16: 1 | AY16: 0 | AZ16: 1
A17: 2025221596534 | B17: 2025 | C17: 221596534 | D17: 383494 | E17: 252167 | F17: -2.24275 | G17: 52.16752 | H17: 22 | I17: 3 | J17: =VLOOKUP(I17, Lookups!$B$1:$C$4, 2, FALSE) -> Slight | K17: 2 | L17: 1 | M17: 45807 | N17: 6 | O17: =VLOOKUP(N17, Lookups!$B$6:$C$12, 2, FALSE) -> Friday | P17: 0.59375 | Q17: -1 | R17: E07000235 | S17: E10000034 | T17: E10000034 | U17: 3 | V17: =VLOOKUP(U17, Lookups!$B$51:$C$57, 2, FALSE) -> A | W17: 449 | X17: =V17&W17 -> A449 | Y17: 1 | Z17: =VLOOKUP(Y17, Lookups!$B$14:$C$21, 2, FALSE) -> Roundabout | AA17: 40 | AB17: -1 | AC17: -1 | AD17: 4 | AE17: 3 | AF17: 4440 | AG17: -1 | AH17: -1 | AI17: 0 | AJ17: 1 | AK17: =VLOOKUP(AJ17, Lookups!$B$23:$C$28, 2, FALSE) -> Daylight | AL17: 1 | AM17: =VLOOKUP(AL17, Lookups!$B$30:$C$39, 2, FALSE) -> Fine / Clear | AN17: 1 | AO17: =VLOOKUP(AN17, Lookups!$B$41:$C$49, 2, FALSE) -> Dry | AP17: -1 | AQ17: -1 | AR17: 0 | AS17: 2 | AT17: 1 | AU17: 2 | AV17: E01032207 | AW17: 3 | AX17: 1 | AY17: 0 | AZ17: 1
A18: 2025221649017 | B18: 2025 | C18: 221649017 | D18: 386356 | E18: 259049 | F18: -2.20118 | G18: 52.22947 | H18: 22 | I18: 3 | J18: =VLOOKUP(I18, Lookups!$B$1:$C$4, 2, FALSE) -> Slight | K18: 2 | L18: 1 | M18: 45931 | N18: 4 | O18: =VLOOKUP(N18, Lookups!$B$6:$C$12, 2, FALSE) -> Wednesday | P18: 0.66666667 | Q18: -1 | R18: E07000238 | S18: E10000034 | T18: E10000034 | U18: 6 | V18: =VLOOKUP(U18, Lookups!$B$51:$C$57, 2, FALSE) -> Unclassified | W18: 0 | X18: Unclassified | Y18: 6 | Z18: =VLOOKUP(Y18, Lookups!$B$14:$C$21, 2, FALSE) -> Single carriageway | AA18: 30 | AB18: -1 | AC18: 13 | AD18: 4 | AE18: 6 | AF18: 0 | AG18: -1 | AH18: -1 | AI18: 0 | AJ18: 1 | AK18: =VLOOKUP(AJ18, Lookups!$B$23:$C$28, 2, FALSE) -> Daylight | AL18: 1 | AM18: =VLOOKUP(AL18, Lookups!$B$30:$C$39, 2, FALSE) -> Fine / Clear | AN18: 1 | AO18: =VLOOKUP(AN18, Lookups!$B$41:$C$49, 2, FALSE) -> Dry | AP18: -1 | AQ18: -1 | AR18: 0 | AS18: 2 | AT18: 3 | AU18: 2 | AV18: E01032399 | AW18: 3 | AX18: 1 | AY18: 0 | AZ18: 1
A19: 2025221537191 | B19: 2025 | C19: 221537191 | D19: 403501 | E19: 243533 | F19: -1.95032 | G19: 52.09013 | H19: 22 | I19: 2 | J19: =VLOOKUP(I19, Lookups!$B$1:$C$4, 2, FALSE) -> Serious | K19: 1 | L19: 1 | M19: 45660 | N19: 6 | O19: =VLOOKUP(N19, Lookups!$B$6:$C$12, 2, FALSE) -> Friday | P19: 0.44027778 | Q19: -1 | R19: E07000238 | S19: E10000034 | T19: E10000034 | U19: 3 | V19: =VLOOKUP(U19, Lookups!$B$51:$C$57, 2, FALSE) -> A | W19: 4184 | X19: =V19&W19 -> A4184 | Y19: 6 | Z19: =VLOOKUP(Y19, Lookups!$B$14:$C$21, 2, FALSE) -> Single carriageway | AA19: 30 | AB19: -1 | AC19: 0 | AD19: -1 | AE19: 6 | AF19: 0 | AG19: -1 | AH19: -1 | AI19: 0 | AJ19: 1 | AK19: =VLOOKUP(AJ19, Lookups!$B$23:$C$28, 2, FALSE) -> Daylight | AL19: 1 | AM19: =VLOOKUP(AL19, Lookups!$B$30:$C$39, 2, FALSE) -> Fine / Clear | AN19: 1 | AO19: =VLOOKUP(AN19, Lookups!$B$41:$C$49, 2, FALSE) -> Dry | AP19: -1 | AQ19: -1 | AR19: 0 | AS19: 1 | AT19: 1 | AU19: 2 | AV19: E01034329 | AW19: 7 | AX19: 1 | AY19: 1 | AZ19: 0
A20: 2025221577340 | B20: 2025 | C20: 221577340 | D20: 385847 | E20: 254436 | F20: -2.20844 | G20: 52.18798 | H20: 22 | I20: 3 | J20: =VLOOKUP(I20, Lookups!$B$1:$C$4, 2, FALSE) -> Slight | K20: 1 | L20: 1 | M20: 45759 | N20: 7 | O20: =VLOOKUP(N20, Lookups!$B$6:$C$12, 2, FALSE) -> Saturday | P20: 0.71875 | Q20: -1 | R20: E07000237 | S20: E10000034 | T20: E10000034 | U20: 6 | V20: =VLOOKUP(U20, Lookups!$B$51:$C$57, 2, FALSE) -> Unclassified | W20: 0 | X20: Unclassified | Y20: 6 | Z20: =VLOOKUP(Y20, Lookups!$B$14:$C$21, 2, FALSE) -> Single carriageway | AA20: 30 | AB20: -1 | AC20: 13 | AD20: 1 | AE20: 6 | AF20: 0 | AG20: -1 | AH20: -1 | AI20: 0 | AJ20: 1 | AK20: =VLOOKUP(AJ20, Lookups!$B$23:$C$28, 2, FALSE) -> Daylight | AL20: 1 | AM20: =VLOOKUP(AL20, Lookups!$B$30:$C$39, 2, FALSE) -> Fine / Clear | AN20: 1 | AO20: =VLOOKUP(AN20, Lookups!$B$41:$C$49, 2, FALSE) -> Dry | AP20: -1 | AQ20: -1 | AR20: 0 | AS20: 1 | AT20: 1 | AU20: 2 | AV20: E01032292 | AW20: 3 | AX20: 1 | AY20: 0 | AZ20: 1
A21: 2025221586216 | B21: 2025 | C21: 221586216 | D21: 405886 | E21: 265584 | F21: -1.91513 | G21: 52.28836 | H21: 22 | I21: 1 | J21: =VLOOKUP(I21, Lookups!$B$1:$C$4, 2, FALSE) -> Fatal | K21: 2 | L21: 3 | M21: 45782 | N21: 2 | O21: =VLOOKUP(N21, Lookups!$B$6:$C$12, 2, FALSE) -> Monday | P21: 0.52222222 | Q21: -1 | R21: E07000236 | S21: E10000034 | T21: E10000034 | U21: 6 | V21: =VLOOKUP(U21, Lookups!$B$51:$C$57, 2, FALSE) -> Unclassified | W21: 0 | X21: Unclassified | Y21: 6 | Z21: =VLOOKUP(Y21, Lookups!$B$14:$C$21, 2, FALSE) -> Single carriageway | AA21: 30 | AB21: -1 | AC21: 13 | AD21: 4 | AE21: 6 | AF21: 0 | AG21: -1 | AH21: -1 | AI21: 0 | AJ21: 1 | AK21: =VLOOKUP(AJ21, Lookups!$B$23:$C$28, 2, FALSE) -> Daylight | AL21: 1 | AM21: =VLOOKUP(AL21, Lookups!$B$30:$C$39, 2, FALSE) -> Fine / Clear | AN21: 1 | AO21: =VLOOKUP(AN21, Lookups!$B$41:$C$49, 2, FALSE) -> Dry | AP21: -1 | AQ21: -1 | AR21: 12 | AS21: 1 | AT21: 1 | AU21: 2 | AV21: E01032253 | AW21: 1 | AX21: 1 | AY21: 0 | AZ21: 0
A22: 2025221607209 | B22: 2025 | C22: 221607209 | D22: 395899 | E22: 270799 | F22: -2.06161 | G22: 52.33526 | H22: 22 | I22: 3 | J22: =VLOOKUP(I22, Lookups!$B$1:$C$4, 2, FALSE) -> Slight | K22: 1 | L22: 1 | M22: 45831 | N22: 2 | O22: =VLOOKUP(N22, Lookups!$B$6:$C$12, 2, FALSE) -> Monday | P22: 0.51388889 | Q22: -1 | R22: E07000234 | S22: E10000034 | T22: E10000034 | U22: 6 | V22: =VLOOKUP(U22, Lookups!$B$51:$C$57, 2, FALSE) -> Unclassified | W22: 0 | X22: Unclassified | Y22: 6 | Z22: =VLOOKUP(Y22, Lookups!$B$14:$C$21, 2, FALSE) -> Single carriageway | AA22: 30 | AB22: -1 | AC22: 13 | AD22: 4 | AE22: 6 | AF22: 0 | AG22: -1 | AH22: -1 | AI22: 0 | AJ22: 1 | AK22: =VLOOKUP(AJ22, Lookups!$B$23:$C$28, 2, FALSE) -> Daylight | AL22: 1 | AM22: =VLOOKUP(AL22, Lookups!$B$30:$C$39, 2, FALSE) -> Fine / Clear | AN22: 1 | AO22: =VLOOKUP(AN22, Lookups!$B$41:$C$49, 2, FALSE) -> Dry | AP22: -1 | AQ22: -1 | AR22: 0 | AS22: 1 | AT22: 1 | AU22: 2 | AV22: E01032156 | AW22: 3 | AX22: 1 | AY22: 0 | AZ22: 1
A23: 2025221647090 | B23: 2025 | C23: 221647090 | D23: 406109 | E23: 249057 | F23: -1.91215 | G23: 52.13978 | H23: 22 | I23: 2 | J23: =VLOOKUP(I23, Lookups!$B$1:$C$4, 2, FALSE) -> Serious | K23: 3 | L23: 1 | M23: 45925 | N23: 5 | O23: =VLOOKUP(N23, Lookups!$B$6:$C$12, 2, FALSE) -> Thursday | P23: 0.75 | Q23: -1 | R23: E07000238 | S23: E10000034 | T23: E10000034 | U23: 6 | V23: =VLOOKUP(U23, Lookups!$B$51:$C$57, 2, FALSE) -> Unclassified | W23: 0 | X23: Unclassified | Y23: 6 | Z23: =VLOOKUP(Y23, Lookups!$B$14:$C$21, 2, FALSE) -> Single carriageway | AA23: 60 | AB23: -1 | AC23: 13 | AD23: 4 | AE23: 6 | AF23: 0 | AG23: -1 | AH23: -1 | AI23: 0 | AJ23: 1 | AK23: =VLOOKUP(AJ23, Lookups!$B$23:$C$28, 2, FALSE) -> Daylight | AL23: 1 | AM23: =VLOOKUP(AL23, Lookups!$B$30:$C$39, 2, FALSE) -> Fine / Clear | AN23: 1 | AO23: =VLOOKUP(AN23, Lookups!$B$41:$C$49, 2, FALSE) -> Dry | AP23: -1 | AQ23: -1 | AR23: 0 | AS23: 2 | AT23: 1 | AU23: 2 | AV23: E01032388 | AW23: 7 | AX23: 1 | AY23: 1 | AZ23: 0
A24: 2025221550825 | B24: 2025 | C24: 221550825 | D24: 404092 | E24: 243648 | F24: -1.94169 | G24: 52.09116 | H24: 22 | I24: 3 | J24: =VLOOKUP(I24, Lookups!$B$1:$C$4, 2, FALSE) -> Slight | K24: 2 | L24: 1 | M24: 45666 | N24: 5 | O24: =VLOOKUP(N24, Lookups!$B$6:$C$12, 2, FALSE) -> Thursday | P24: 0.51388889 | Q24: -1 | R24: E07000238 | S24: E10000034 | T24: E10000034 | U24: 4 | V24: =VLOOKUP(U24, Lookups!$B$51:$C$57, 2, FALSE) -> B | W24: 4035 | X24: =V24&W24 -> B4035 | Y24: 6 | Z24: =VLOOKUP(Y24, Lookups!$B$14:$C$21, 2, FALSE) -> Single carriageway | AA24: 30 | AB24: -1 | AC24: 13 | AD24: 2 | AE24: 6 | AF24: 0 | AG24: -1 | AH24: -1 | AI24: 0 | AJ24: 1 | AK24: =VLOOKUP(AJ24, Lookups!$B$23:$C$28, 2, FALSE) -> Daylight | AL24: 1 | AM24: =VLOOKUP(AL24, Lookups!$B$30:$C$39, 2, FALSE) -> Fine / Clear | AN24: 1 | AO24: =VLOOKUP(AN24, Lookups!$B$41:$C$49, 2, FALSE) -> Dry | AP24: -1 | AQ24: -1 | AR24: 0 | AS24: 1 | AT24: 1 | AU24: 2 | AV24: E01034329 | AW24: 3 | AX24: 1 | AY24: 0 | AZ24: 1
A25: 2025221557272 | B25: 2025 | C25: 221557272 | D25: 392552 | E25: 281366 | F25: -2.11097 | G25: 52.43022 | H25: 22 | I25: 2 | J25: =VLOOKUP(I25, Lookups!$B$1:$C$4, 2, FALSE) -> Serious | K25: 2 | L25: 1 | M25: 45710 | N25: 7 | O25: =VLOOKUP(N25, Lookups!$B$6:$C$12, 2, FALSE) -> Saturday | P25: 0.71458333 | Q25: -1 | R25: E07000234 | S25: E10000034 | T25: E10000034 | U25: 3 | V25: =VLOOKUP(U25, Lookups!$B$51:$C$57, 2, FALSE) -> A | W25: 456 | X25: =V25&W25 -> A456 | Y25: 3 | Z25: =VLOOKUP(Y25, Lookups!$B$14:$C$21, 2, FALSE) -> Dual carriageway | AA25: 60 | AB25: -1 | AC25: 17 | AD25: 4 | AE25: 3 | AF25: 456 | AG25: -1 | AH25: -1 | AI25: 0 | AJ25: 4 | AK25: =VLOOKUP(AJ25, Lookups!$B$23:$C$28, 2, FALSE) -> Darkness (Lit) | AL25: 1 | AM25: =VLOOKUP(AL25, Lookups!$B$30:$C$39, 2, FALSE) -> Fine / Clear | AN25: 1 | AO25: =VLOOKUP(AN25, Lookups!$B$41:$C$49, 2, FALSE) -> Dry | AP25: -1 | AQ25: -1 | AR25: 0 | AS25: 2 | AT25: 1 | AU25: 2 | AV25: E01032141 | AW25: 7 | AX25: 1 | AY25: 1 | AZ25: 0
A26: 2025221587020 | B26: 2025 | C26: 221587020 | D26: 389533 | E26: 263319 | F26: -2.1548 | G26: 52.26793 | H26: 22 | I26: 3 | J26: =VLOOKUP(I26, Lookups!$B$1:$C$4, 2, FALSE) -> Slight | K26: 2 | L26: 1 | M26: 45784 | N26: 4 | O26: =VLOOKUP(N26, Lookups!$B$6:$C$12, 2, FALSE) -> Wednesday | P26: 0.88888889 | Q26: -1 | R26: E07000238 | S26: E10000034 | T26: E10000034 | U26: 6 | V26: =VLOOKUP(U26, Lookups!$B$51:$C$57, 2, FALSE) -> Unclassified | W26: 0 | X26: Unclassified | Y26: 6 | Z26: =VLOOKUP(Y26, Lookups!$B$14:$C$21, 2, FALSE) -> Single carriageway | AA26: 30 | AB26: -1 | AC26: 13 | AD26: 4 | AE26: 6 | AF26: 0 | AG26: -1 | AH26: -1 | AI26: 0 | AJ26: 1 | AK26: =VLOOKUP(AJ26, Lookups!$B$23:$C$28, 2, FALSE) -> Daylight | AL26: 1 | AM26: =VLOOKUP(AL26, Lookups!$B$30:$C$39, 2, FALSE) -> Fine / Clear | AN26: 1 | AO26: =VLOOKUP(AN26, Lookups!$B$41:$C$49, 2, FALSE) -> Dry | AP26: -1 | AQ26: -1 | AR26: 0 | AS26: 1 | AT26: 3 | AU26: 2 | AV26: E01032358 | AW26: 3 | AX26: 1 | AY26: 0 | AZ26: 1
A27: 2025221592189 | B27: 2025 | C27: 221592189 | D27: 388154 | E27: 254249 | F27: -2.17469 | G27: 52.18636 | H27: 22 | I27: 3 | J27: =VLOOKUP(I27, Lookups!$B$1:$C$4, 2, FALSE) -> Slight | K27: 2 | L27: 1 | M27: 45796 | N27: 2 | O27: =VLOOKUP(N27, Lookups!$B$6:$C$12, 2, FALSE) -> Monday | P27: 0.41666667 | Q27: -1 | R27: E07000237 | S27: E10000034 | T27: E10000034 | U27: 3 | V27: =VLOOKUP(U27, Lookups!$B$51:$C$57, 2, FALSE) -> A | W27: 4440 | X27: =V27&W27 -> A4440 | Y27: 3 | Z27: =VLOOKUP(Y27, Lookups!$B$14:$C$21, 2, FALSE) -> Dual carriageway | AA27: 40 | AB27: -1 | AC27: -1 | AD27: 4 | AE27: 3 | AF27: 4440 | AG27: -1 | AH27: -1 | AI27: 14 | AJ27: 1 | AK27: =VLOOKUP(AJ27, Lookups!$B$23:$C$28, 2, FALSE) -> Daylight | AL27: 1 | AM27: =VLOOKUP(AL27, Lookups!$B$30:$C$39, 2, FALSE) -> Fine / Clear | AN27: 1 | AO27: =VLOOKUP(AN27, Lookups!$B$41:$C$49, 2, FALSE) -> Dry | AP27: -1 | AQ27: -1 | AR27: 0 | AS27: 2 | AT27: 3 | AU27: 2 | AV27: E01032339 | AW27: 3 | AX27: 1 | AY27: 0 | AZ27: 1
A28: 2025221633599 | B28: 2025 | C28: 221633599 | D28: 374811 | E28: 266224 | F28: -2.37075 | G28: 52.29356 | H28: 22 | I28: 2 | J28: =VLOOKUP(I28, Lookups!$B$1:$C$4, 2, FALSE) -> Serious | K28: 1 | L28: 1 | M28: 45894 | N28: 2 | O28: =VLOOKUP(N28, Lookups!$B$6:$C$12, 2, FALSE) -> Monday | P28: 0.47222222 | Q28: -1 | R28: E07000235 | S28: E10000034 | T28: E10000034 | U28: 4 | V28: =VLOOKUP(U28, Lookups!$B$51:$C$57, 2, FALSE) -> B | W28: 4203 | X28: =V28&W28 -> B4203 | Y28: 6 | Z28: =VLOOKUP(Y28, Lookups!$B$14:$C$21, 2, FALSE) -> Single carriageway | AA28: 60 | AB28: -1 | AC28: 0 | AD28: -1 | AE28: 0 | AF28: -1 | AG28: -1 | AH28: -1 | AI28: 0 | AJ28: 1 | AK28: =VLOOKUP(AJ28, Lookups!$B$23:$C$28, 2, FALSE) -> Daylight | AL28: 1 | AM28: =VLOOKUP(AL28, Lookups!$B$30:$C$39, 2, FALSE) -> Fine / Clear | AN28: 1 | AO28: =VLOOKUP(AN28, Lookups!$B$41:$C$49, 2, FALSE) -> Dry | AP28: -1 | AQ28: -1 | AR28: 0 | AS28: 2 | AT28: 1 | AU28: 2 | AV28: E01032223 | AW28: 7 | AX28: 1 | AY28: 1 | AZ28: 0
A29: 2025221665189 | B29: 2025 | C29: 221665189 | D29: 403859 | E29: 275468 | F29: -1.94474 | G29: 52.37724 | H29: 22 | I29: 3 | J29: =VLOOKUP(I29, Lookups!$B$1:$C$4, 2, FALSE) -> Slight | K29: 3 | L29: 1 | M29: 45968 | N29: 6 | O29: =VLOOKUP(N29, Lookups!$B$6:$C$12, 2, FALSE) -> Friday | P29: 0.66666667 | Q29: -1 | R29: E07000234 | S29: E10000034 | T29: E10000034 | U29: 6 | V29: =VLOOKUP(U29, Lookups!$B$51:$C$57, 2, FALSE) -> Unclassified | W29: 0 | X29: Unclassified | Y29: 6 | Z29: =VLOOKUP(Y29, Lookups!$B$14:$C$21, 2, FALSE) -> Single carriageway | AA29: 30 | AB29: -1 | AC29: 0 | AD29: -1 | AE29: 0 | AF29: -1 | AG29: -1 | AH29: -1 | AI29: 0 | AJ29: 1 | AK29: =VLOOKUP(AJ29, Lookups!$B$23:$C$28, 2, FALSE) -> Daylight | AL29: 1 | AM29: =VLOOKUP(AL29, Lookups!$B$30:$C$39, 2, FALSE) -> Fine / Clear | AN29: 1 | AO29: =VLOOKUP(AN29, Lookups!$B$41:$C$49, 2, FALSE) -> Dry | AP29: -1 | AQ29: -1 | AR29: 0 | AS29: 2 | AT29: 3 | AU29: 2 | AV29: E01032122 | AW29: 3 | AX29: 1 | AY29: 0 | AZ29: 1
A30: 2025221675428 | B30: 2025 | C30: 221675428 | D30: 404221 | E30: 246672 | F30: -1.93977 | G30: 52.11835 | H30: 22 | I30: 3 | J30: =VLOOKUP(I30, Lookups!$B$1:$C$4, 2, FALSE) -> Slight | K30: 4 | L30: 1 | M30: 45989 | N30: 6 | O30: =VLOOKUP(N30, Lookups!$B$6:$C$12, 2, FALSE) -> Friday | P30: 0.71527778 | Q30: -1 | R30: E07000238 | S30: E10000034 | T30: E10000034 | U30: 3 | V30: =VLOOKUP(U30, Lookups!$B$51:$C$57, 2, FALSE) -> A | W30: 46 | X30: =V30&W30 -> A46 | Y30: 3 | Z30: =VLOOKUP(Y30, Lookups!$B$14:$C$21, 2, FALSE) -> Dual carriageway | AA30: 70 | AB30: -1 | AC30: 0 | AD30: -1 | AE30: 0 | AF30: -1 | AG30: -1 | AH30: -1 | AI30: 0 | AJ30: 6 | AK30: =VLOOKUP(AJ30, Lookups!$B$23:$C$28, 2, FALSE) -> Darkness (Unlit) | AL30: 1 | AM30: =VLOOKUP(AL30, Lookups!$B$30:$C$39, 2, FALSE) -> Fine / Clear | AN30: 2 | AO30: =VLOOKUP(AN30, Lookups!$B$41:$C$49, 2, FALSE) -> Wet / damp | AP30: -1 | AQ30: -1 | AR30: 0 | AS30: 2 | AT30: 1 | AU30: 1 | AV30: E01032389 | AW30: 3 | AX30: 1 | AY30: 0 | AZ30: 1
A31: 2025221553446 | B31: 2025 | C31: 221553446 | D31: 375163 | E31: 260193 | F31: -2.36514 | G31: 52.23936 | H31: 22 | I31: 3 | J31: =VLOOKUP(I31, Lookups!$B$1:$C$4, 2, FALSE) -> Slight | K31: 1 | L31: 1 | M31: 45698 | N31: 2 | O31: =VLOOKUP(N31, Lookups!$B$6:$C$12, 2, FALSE) -> Monday | P31: 0.67847222 | Q31: -1 | R31: E07000235 | S31: E10000034 | T31: E10000034 | U31: 4 | V31: =VLOOKUP(U31, Lookups!$B$51:$C$57, 2, FALSE) -> B | W31: 4204 | X31: =V31&W31 -> B4204 | Y31: 6 | Z31: =VLOOKUP(Y31, Lookups!$B$14:$C$21, 2, FALSE) -> Single carriageway | AA31: 60 | AB31: -1 | AC31: 0 | AD31: -1 | AE31: 6 | AF31: 0 | AG31: -1 | AH31: -1 | AI31: 0 | AJ31: 1 | AK31: =VLOOKUP(AJ31, Lookups!$B$23:$C$28, 2, FALSE) -> Daylight | AL31: 1 | AM31: =VLOOKUP(AL31, Lookups!$B$30:$C$39, 2, FALSE) -> Fine / Clear | AN31: 1 | AO31: =VLOOKUP(AN31, Lookups!$B$41:$C$49, 2, FALSE) -> Dry | AP31: -1 | AQ31: -1 | AR31: 0 | AS31: 2 | AT31: 1 | AU31: 2 | AV31: E01032199 | AW31: 3 | AX31: 1 | AY31: 0 | AZ31: 1
A32: 2025221679936 | B32: 2025 | C32: 221679936 | D32: 388416 | E32: 254935 | F32: -2.17088 | G32: 52.19253 | H32: 22 | I32: 3 | J32: =VLOOKUP(I32, Lookups!$B$1:$C$4, 2, FALSE) -> Slight | K32: 1 | L32: 2 | M32: 45999 | N32: 2 | O32: =VLOOKUP(N32, Lookups!$B$6:$C$12, 2, FALSE) -> Monday | P32: 0.58333333 | Q32: -1 | R32: E07000237 | S32: E10000034 | T32: E10000034 | U32: 3 | V32: =VLOOKUP(U32, Lookups!$B$51:$C$57, 2, FALSE) -> A | W32: 4440 | X32: =V32&W32 -> A4440 | Y32: 1 | Z32: =VLOOKUP(Y32, Lookups!$B$14:$C$21, 2, FALSE) -> Roundabout | AA32: 60 | AB32: -1 | AC32: -1 | AD32: 4 | AE32: 4 | AF32: 4636 | AG32: -1 | AH32: -1 | AI32: 0 | AJ32: 1 | AK32: =VLOOKUP(AJ32, Lookups!$B$23:$C$28, 2, FALSE) -> Daylight | AL32: 1 | AM32: =VLOOKUP(AL32, Lookups!$B$30:$C$39, 2, FALSE) -> Fine / Clear | AN32: 2 | AO32: =VLOOKUP(AN32, Lookups!$B$41:$C$49, 2, FALSE) -> Wet / damp | AP32: -1 | AQ32: -1 | AR32: 0 | AS32: 2 | AT32: 1 | AU32: 2 | AV32: E01032339 | AW32: 3 | AX32: 1 | AY32: 0 | AZ32: 1
A33: 2025221554493 | B33: 2025 | C33: 221554493 | D33: 385407 | E33: 255280 | F33: -2.21491 | G33: 52.19556 | H33: 22 | I33: 2 | J33: =VLOOKUP(I33, Lookups!$B$1:$C$4, 2, FALSE) -> Serious | K33: 1 | L33: 1 | M33: 45702 | N33: 6 | O33: =VLOOKUP(N33, Lookups!$B$6:$C$12, 2, FALSE) -> Friday | P33: 0.77083333 | Q33: -1 | R33: E07000237 | S33: E10000034 | T33: E10000034 | U33: 4 | V33: =VLOOKUP(U33, Lookups!$B$51:$C$57, 2, FALSE) -> B | W33: 4205 | X33: =V33&W33 -> B4205 | Y33: 6 | Z33: =VLOOKUP(Y33, Lookups!$B$14:$C$21, 2, FALSE) -> Single carriageway | AA33: 30 | AB33: -1 | AC33: 19 | AD33: 4 | AE33: 6 | AF33: 0 | AG33: -1 | AH33: -1 | AI33: 0 | AJ33: 4 | AK33: =VLOOKUP(AJ33, Lookups!$B$23:$C$28, 2, FALSE) -> Darkness (Lit) | AL33: 2 | AM33: =VLOOKUP(AL33, Lookups!$B$30:$C$39, 2, FALSE) -> Rain | AN33: 2 | AO33: =VLOOKUP(AN33, Lookups!$B$41:$C$49, 2, FALSE) -> Wet / damp | AP33: -1 | AQ33: -1 | AR33: 0 | AS33: 1 | AT33: 1 | AU33: 2 | AV33: E01033248 | AW33: 7 | AX33: 1 | AY33: 1 | AZ33: 0
A34: 2025221629484 | B34: 2025 | C34: 221629484 | D34: 387340 | E34: 274681 | F34: -2.18737 | G34: 52.37003 | H34: 22 | I34: 3 | J34: =VLOOKUP(I34, Lookups!$B$1:$C$4, 2, FALSE) -> Slight | K34: 2 | L34: 1 | M34: 45884 | N34: 6 | O34: =VLOOKUP(N34, Lookups!$B$6:$C$12, 2, FALSE) -> Friday | P34: 0.82291667 | Q34: -1 | R34: E07000239 | S34: E10000034 | T34: E10000034 | U34: 3 | V34: =VLOOKUP(U34, Lookups!$B$51:$C$57, 2, FALSE) -> A | W34: 450 | X34: =V34&W34 -> A450 | Y34: 6 | Z34: =VLOOKUP(Y34, Lookups!$B$14:$C$21, 2, FALSE) -> Single carriageway | AA34: 40 | AB34: -1 | AC34: 0 | AD34: -1 | AE34: 6 | AF34: 0 | AG34: -1 | AH34: -1 | AI34: 0 | AJ34: 1 | AK34: =VLOOKUP(AJ34, Lookups!$B$23:$C$28, 2, FALSE) -> Daylight | AL34: 1 | AM34: =VLOOKUP(AL34, Lookups!$B$30:$C$39, 2, FALSE) -> Fine / Clear | AN34: 1 | AO34: =VLOOKUP(AN34, Lookups!$B$41:$C$49, 2, FALSE) -> Dry | AP34: -1 | AQ34: -1 | AR34: 0 | AS34: 2 | AT34: 1 | AU34: 2 | AV34: E01032432 | AW34: 3 | AX34: 1 | AY34: 0 | AZ34: 1
A35: 2025221630164 | B35: 2025 | C35: 221630164 | D35: 388000 | E35: 262897 | F35: -2.17725 | G35: 52.2641 | H35: 22 | I35: 1 | J35: =VLOOKUP(I35, Lookups!$B$1:$C$4, 2, FALSE) -> Fatal | K35: 2 | L35: 1 | M35: 45886 | N35: 1 | O35: =VLOOKUP(N35, Lookups!$B$6:$C$12, 2, FALSE) -> Sunday | P35: 0.63888889 | Q35: -1 | R35: E07000238 | S35: E10000034 | T35: E10000034 | U35: 3 | V35: =VLOOKUP(U35, Lookups!$B$51:$C$57, 2, FALSE) -> A | W35: 4133 | X35: =V35&W35 -> A4133 | Y35: 1 | Z35: =VLOOKUP(Y35, Lookups!$B$14:$C$21, 2, FALSE) -> Roundabout | AA35: 60 | AB35: -1 | AC35: -1 | AD35: 4 | AE35: 3 | AF35: 38 | AG35: -1 | AH35: -1 | AI35: 0 | AJ35: 1 | AK35: =VLOOKUP(AJ35, Lookups!$B$23:$C$28, 2, FALSE) -> Daylight | AL35: 1 | AM35: =VLOOKUP(AL35, Lookups!$B$30:$C$39, 2, FALSE) -> Fine / Clear | AN35: 1 | AO35: =VLOOKUP(AN35, Lookups!$B$41:$C$49, 2, FALSE) -> Dry | AP35: -1 | AQ35: -1 | AR35: 0 | AS35: 2 | AT35: 1 | AU35: 2 | AV35: E01032370 | AW35: 1 | AX35: 1 | AY35: 0 | AZ35: 0
A36: 2025221618093 | B36: 2025 | C36: 221618093 | D36: 378003 | E36: 233462 | F36: -2.32182 | G36: 51.99916 | H36: 22 | I36: 3 | J36: =VLOOKUP(I36, Lookups!$B$1:$C$4, 2, FALSE) -> Slight | K36: 2 | L36: 1 | M36: 45856 | N36: 6 | O36: =VLOOKUP(N36, Lookups!$B$6:$C$12, 2, FALSE) -> Friday | P36: 0.81805556 | Q36: -1 | R36: E07000235 | S36: E10000034 | T36: E10000034 | U36: 4 | V36: =VLOOKUP(U36, Lookups!$B$51:$C$57, 2, FALSE) -> B | W36: 4208 | X36: =V36&W36 -> B4208 | Y36: 6 | Z36: =VLOOKUP(Y36, Lookups!$B$14:$C$21, 2, FALSE) -> Single carriageway | AA36: 60 | AB36: -1 | AC36: 13 | AD36: 3 | AE36: 6 | AF36: 0 | AG36: -1 | AH36: -1 | AI36: 0 | AJ36: 1 | AK36: =VLOOKUP(AJ36, Lookups!$B$23:$C$28, 2, FALSE) -> Daylight | AL36: 1 | AM36: =VLOOKUP(AL36, Lookups!$B$30:$C$39, 2, FALSE) -> Fine / Clear | AN36: 1 | AO36: =VLOOKUP(AN36, Lookups!$B$41:$C$49, 2, FALSE) -> Dry | AP36: -1 | AQ36: -1 | AR36: 0 | AS36: 2 | AT36: 1 | AU36: 2 | AV36: E01032198 | AW36: 3 | AX36: 1 | AY36: 0 | AZ36: 1
A37: 2025221543333 | B37: 2025 | C37: 221543333 | D37: 409508 | E37: 237508 | F37: -1.86281 | G37: 52.0359 | H37: 22 | I37: 2 | J37: =VLOOKUP(I37, Lookups!$B$1:$C$4, 2, FALSE) -> Serious | K37: 1 | L37: 1 | M37: 45674 | N37: 6 | O37: =VLOOKUP(N37, Lookups!$B$6:$C$12, 2, FALSE) -> Friday | P37: 0.55763889 | Q37: -1 | R37: E07000238 | S37: E10000034 | T37: E10000034 | U37: 6 | V37: =VLOOKUP(U37, Lookups!$B$51:$C$57, 2, FALSE) -> Unclassified | W37: 0 | X37: Unclassified | Y37: 6 | Z37: =VLOOKUP(Y37, Lookups!$B$14:$C$21, 2, FALSE) -> Single carriageway | AA37: 30 | AB37: -1 | AC37: 0 | AD37: -1 | AE37: 6 | AF37: 0 | AG37: -1 | AH37: -1 | AI37: 0 | AJ37: 1 | AK37: =VLOOKUP(AJ37, Lookups!$B$23:$C$28, 2, FALSE) -> Daylight | AL37: 1 | AM37: =VLOOKUP(AL37, Lookups!$B$30:$C$39, 2, FALSE) -> Fine / Clear | AN37: 1 | AO37: =VLOOKUP(AN37, Lookups!$B$41:$C$49, 2, FALSE) -> Dry | AP37: -1 | AQ37: -1 | AR37: 0 | AS37: 2 | AT37: 1 | AU37: 2 | AV37: E01032353 | AW37: 6 | AX37: 1 | AY37: 1 | AZ37: 0
A38: 2025221565797 | B38: 2025 | C38: 221565797 | D38: 382260 | E38: 271460 | F38: -2.26181 | G38: 52.34093 | H38: 22 | I38: 3 | J38: =VLOOKUP(I38, Lookups!$B$1:$C$4, 2, FALSE) -> Slight | K38: 2 | L38: 2 | M38: 45731 | N38: 7 | O38: =VLOOKUP(N38, Lookups!$B$6:$C$12, 2, FALSE) -> Saturday | P38: 0.71527778 | Q38: -1 | R38: E07000239 | S38: E10000034 | T38: E10000034 | U38: 4 | V38: =VLOOKUP(U38, Lookups!$B$51:$C$57, 2, FALSE) -> B | W38: 4193 | X38: =V38&W38 -> B4193 | Y38: 6 | Z38: =VLOOKUP(Y38, Lookups!$B$14:$C$21, 2, FALSE) -> Single carriageway | AA38: 30 | AB38: -1 | AC38: 13 | AD38: 4 | AE38: 6 | AF38: 0 | AG38: -1 | AH38: -1 | AI38: 0 | AJ38: 1 | AK38: =VLOOKUP(AJ38, Lookups!$B$23:$C$28, 2, FALSE) -> Daylight | AL38: 1 | AM38: =VLOOKUP(AL38, Lookups!$B$30:$C$39, 2, FALSE) -> Fine / Clear | AN38: 1 | AO38: =VLOOKUP(AN38, Lookups!$B$41:$C$49, 2, FALSE) -> Dry | AP38: -1 | AQ38: -1 | AR38: 0 | AS38: 1 | AT38: 3 | AU38: 2 | AV38: E01032462 | AW38: 3 | AX38: 1 | AY38: 0 | AZ38: 1
A39: 2025221565483 | B39: 2025 | C39: 221565483 | D39: 381990 | E39: 277698 | F39: -2.26611 | G39: 52.397 | H39: 22 | I39: 2 | J39: =VLOOKUP(I39, Lookups!$B$1:$C$4, 2, FALSE) -> Serious | K39: 4 | L39: 1 | M39: 45731 | N39: 7 | O39: =VLOOKUP(N39, Lookups!$B$6:$C$12, 2, FALSE) -> Saturday | P39: 0.91666667 | Q39: -1 | R39: E07000239 | S39: E10000034 | T39: E10000034 | U39: 3 | V39: =VLOOKUP(U39, Lookups!$B$51:$C$57, 2, FALSE) -> A | W39: 442 | X39: =V39&W39 -> A442 | Y39: 6 | Z39: =VLOOKUP(Y39, Lookups!$B$14:$C$21, 2, FALSE) -> Single carriageway | AA39: 30 | AB39: -1 | AC39: 0 | AD39: -1 | AE39: 6 | AF39: 0 | AG39: -1 | AH39: -1 | AI39: 0 | AJ39: 4 | AK39: =VLOOKUP(AJ39, Lookups!$B$23:$C$28, 2, FALSE) -> Darkness (Lit) | AL39: 1 | AM39: =VLOOKUP(AL39, Lookups!$B$30:$C$39, 2, FALSE) -> Fine / Clear | AN39: 1 | AO39: =VLOOKUP(AN39, Lookups!$B$41:$C$49, 2, FALSE) -> Dry | AP39: -1 | AQ39: -1 | AR39: 0 | AS39: 1 | AT39: 1 | AU39: 2 | AV39: E01032445 | AW39: 5 | AX39: 1 | AY39: 1 | AZ39: 0
A40: 2025221692311 | B40: 2025 | C40: 221692311 | D40: 390008 | E40: 242661 | F40: -2.14723 | G40: 52.08221 | H40: 22 | I40: 3 | J40: =VLOOKUP(I40, Lookups!$B$1:$C$4, 2, FALSE) -> Slight | K40: 1 | L40: 1 | M40: 46021 | N40: 3 | O40: =VLOOKUP(N40, Lookups!$B$6:$C$12, 2, FALSE) -> Tuesday | P40: 0.67916667 | Q40: -1 | R40: E07000238 | S40: E10000034 | T40: E10000034 | U40: 3 | V40: =VLOOKUP(U40, Lookups!$B$51:$C$57, 2, FALSE) -> A | W40: 4104 | X40: =V40&W40 -> A4104 | Y40: 6 | Z40: =VLOOKUP(Y40, Lookups!$B$14:$C$21, 2, FALSE) -> Single carriageway | AA40: 60 | AB40: -1 | AC40: 0 | AD40: -1 | AE40: 6 | AF40: 0 | AG40: -1 | AH40: -1 | AI40: 0 | AJ40: 6 | AK40: =VLOOKUP(AJ40, Lookups!$B$23:$C$28, 2, FALSE) -> Darkness (Unlit) | AL40: 1 | AM40: =VLOOKUP(AL40, Lookups!$B$30:$C$39, 2, FALSE) -> Fine / Clear | AN40: 2 | AO40: =VLOOKUP(AN40, Lookups!$B$41:$C$49, 2, FALSE) -> Wet / damp | AP40: -1 | AQ40: -1 | AR40: 0 | AS40: 2 | AT40: 1 | AU40: 2 | AV40: E01032372 | AW40: 3 | AX40: 1 | AY40: 0 | AZ40: 1
...

Sheet Lookups
A1: Field name | B1: Code | C1: Label
A2: collision_severity | B2: 1 | C2: Fatal
A3: collision_severity | B3: 2 | C3: Serious
A4: collision_severity | B4: 3 | C4: Slight
A6: day_of_week | B6: 1 | C6: Sunday
A7: day_of_week | B7: 2 | C7: Monday
A8: day_of_week | B8: 3 | C8: Tuesday
A9: day_of_week | B9: 4 | C9: Wednesday
A10: day_of_week | B10: 5 | C10: Thursday
A11: day_of_week | B11: 6 | C11: Friday
A12: day_of_week | B12: 7 | C12: Saturday
A14: road_type | B14: 1 | C14: Roundabout
A15: road_type | B15: 2 | C15: One way street
... A57: first_road_class | B57: -1 | C57: Data missing
A59: first_road_number | B59: 1 to 9999 | C59: Number range
A60: first_road_number | B60: -1 | C60: Unknown
A61: first_road_number | B61: 0 | C61: first_road_class is C or Unclassified. These roads do not have official numbers so recorded as zero
